<robot xmlns:xacro="http://www.ros.org/wiki/xacro" name="my_robot">

  <xacro:include filename="$(find my_robot)/urdf/my_robot.gazebo" />
  
  <material name="red">
    <color rgba="0.8 0.0 0.0 1.0"/>
  </material>

  <material name="blue">
    <color rgba="0.0 0.0 0.8 1.0"/>
  </material>

  <material name="green">
    <color rgba="0.0 0.8 0.0 1.0"/>
  </material>

  <link name="robot_footprint"></link>

  <joint name="robot_footprint_joint" type="fixed">
    <origin xyz="0 0 0" rpy="0 0 0" />
    <parent link="robot_footprint"/>
    <child link="chassis" />
  </joint>

  // Chassis
  <link name='chassis'>
    <!-- <pose>0 0 0.1 0 0 0</pose> -->

    <inertial>
      <mass value="15.0"/>
      <origin xyz="0.0 0 0" rpy=" 0 0 0"/>
      <inertia
          ixx="0.1" ixy="0" ixz="0"
          iyy="0.1" iyz="0"
          izz="0.1"
      />
    </inertial>

    <collision name='collision'>
      <origin xyz="0 0 0" rpy=" 0 0 0"/> 
      <geometry>
        <box size=".4 .2 .1"/>
      </geometry>
    </collision>

    <visual name='chassis_visual'>
      <origin xyz="0 0 0" rpy=" 0 0 0"/>
      <geometry>
        <box size=".4 .2 .1"/>
      </geometry>
      <material name="blue"/>
    </visual>

    // Back Caster
    <collision name='back_caster_collision'>
      <origin xyz="-0.15 0 -0.05" rpy=" 0 0 0"/>
      <geometry>
        <sphere radius="0.0499"/>
      </geometry>
    </collision>

    <visual name='back_caster_visual'>
      <origin xyz="-0.15 0 -0.05" rpy=" 0 0 0"/>
      <geometry>
        <sphere radius="0.05"/>
      </geometry>
    </visual>

    // Front Caster
    <collision name='front_caster_collision'>
      <origin xyz="0.15 0 -0.05" rpy=" 0 0 0"/>
      <geometry>
        <sphere radius="0.0499"/>
      </geometry>
    </collision>

    <visual name='front_caster_visual'>
      <origin xyz="0.15 0 -0.05" rpy=" 0 0 0"/>
      <geometry>
        <sphere radius="0.05"/>
      </geometry>
    </visual>
  </link>
  
  // Left Wheel
  <link name="left_wheel">
    <inertial>
      <mass value="5.0"/>
      <origin xyz="0.0 0 0" rpy=" 0 0 0"/>
      <inertia
          ixx="0.1" ixy="0" ixz="0"
          iyy="0.1" iyz="0"
          izz="0.1"
      />
    </inertial>
    <collision name="left_wheel_collision">
        <origin xyz="0.0 0.0 0.0" rpy="0.0 1.5707 1.5707"/>
        <geometry>
            <cylinder radius="0.1" length="0.05"/>
        </geometry>
    </collision>
    <visual name="left_wheel_visual">
        <origin xyz="0.0 0.0 0.0" rpy="0.0 1.5707 1.5707"/>
        <geometry>
            <cylinder radius="0.1" length="0.05"/> 
        </geometry>
        <material name="red"/>
    </visual>
  </link>

  // Left Joint
  <joint type="continuous" name="left_wheel_hinge">
    <origin xyz="0 0.12 0" rpy="0 0 0"/>
    <child link="left_wheel"/>
    <parent link="chassis"/>
    <axis xyz="0 1 0" rpy="0 0 0"/>
    <limit effort="10000" velocity="1000"/>
    <dynamics damping="1.0" friction="1.0"/>
  </joint>

  // Right Wheel
  <link name="right_wheel">
    <inertial>
      <mass value="5.0"/>
      <origin xyz="0.0 0 0" rpy=" 0 0 0"/>
      <inertia
          ixx="0.1" ixy="0" ixz="0"
          iyy="0.1" iyz="0"
          izz="0.1"
      />
    </inertial>
    <collision name="right_wheel_collision">
        <origin xyz="0.0 0.0 0.0" rpy="0.0 1.5707 1.5707"/>
        <geometry>
            <cylinder radius="0.1" length="0.05"/>
        </geometry>
    </collision>
    <visual name="right_wheel_visual">
        <origin xyz="0.0 0.0 0.0" rpy="0.0 1.5707 1.5707"/>
        <geometry>
            <cylinder radius="0.1" length="0.05"/> 
        </geometry>
        <material name="red"/>
    </visual>
  </link>

  // Right Joint
  <joint type="continuous" name="right_wheel_hinge">
    <origin xyz="0 -0.12 0" rpy="0 0 0"/>
    <child link="right_wheel"/>
    <parent link="chassis"/>
    <axis xyz="0 1 0" rpy="0 0 0"/>
    <limit effort="10000" velocity="1000"/>
    <dynamics damping="1.0" friction="1.0"/>
  </joint>

  // Camera Joint
  <joint name="camera_joint" type="fixed">
    <origin xyz="0.2 0.0 0.0" rpy="0.0 0.0 0.0"/>
    <parent link="chassis"/>
    <child link="camera"/>
    <axis xyz="0.0 1 0.0"/>
  </joint>

  // Camera
  <link name="camera">
    <collision>
      <origin xyz="0 0 0" rpy="0 0 0"/>
      <geometry>
        <box size="0.001 0.001 0.001"/>
      </geometry>
    </collision>

    <visual>
      <origin xyz="0 0 0" rpy="0 0 0"/>
      <geometry>
        <box size="0.001 0.001 0.001"/>
      </geometry>
    </visual>

    <inertial>
      <mass value="1e-5" />
      <origin xyz="0 0 0" rpy="0 0 0"/>
      <inertia ixx="1e-6" ixy="0" ixz="0" iyy="1e-6" iyz="0" izz="1e-6" />
    </inertial>
  </link>

  // Lidar Joint
  <joint name="lidar_joint" type="fixed">
    <origin xyz="0.0 0.0 0.2" rpy="0.0 0.0 0.0"/>
    <parent link="chassis"/>
    <child link="lidar"/>
    <axis xyz="0.0 1 0.0"/>
  </joint>

  // Lidar
  <link name="lidar" />

  <xacro:include filename="$(find velodyne_description)/urdf/VLP-16.urdf.xacro"/>
  <xacro:VLP-16 parent="lidar" name="velodyne" topic="/velodyne_points" hz="5" samples="350" min_range="0.1" organize_cloud="true">
    <origin xyz="0 0 0" rpy="0 0 0" />
  </xacro:VLP-16>
</robot>
